Workbook

Sheet decay
A1: sec_cd | B1: sec_nm | C1: value | D1: source
A2: 01 | B2: Agriculture - vegetable | C2: =AVERAGEIFS(decay_nem_eu!$D:$D,decay_nem_eu!$C:$C,{"FR";"DE";"IT";"ES";"UK"},decay_nem_eu!$A:$A,"01") -> 0.067090362 | D2: NEMESIS EU (avg value from DE, FR, IT, ES and UK)
A3: 02 | B3: Agriculture - animals | C3: =AVERAGEIFS(decay_nem_eu!$D:$D,decay_nem_eu!$C:$C,{"FR";"DE";"IT";"ES";"UK"},decay_nem_eu!$A:$A,"01") -> 0.067090362 | D3: NEMESIS EU (avg value from DE, FR, IT, ES and UK)
A4: 03 | B4: Forestry | C4: =AVERAGEIFS(decay_nem_eu!$D:$D,decay_nem_eu!$C:$C,{"FR";"DE";"IT";"ES";"UK"},decay_nem_eu!$A:$A,"01") -> 0.067090362 | D4: NEMESIS EU (avg value from DE, FR, IT, ES and UK)
A5: 04 | B5: Fishery | C5: =AVERAGEIFS(decay_nem_eu!$D:$D,decay_nem_eu!$C:$C,{"FR";"DE";"IT";"ES";"UK"},decay_nem_eu!$A:$A,"01") -> 0.067090362 | D5: NEMESIS EU (avg value from DE, FR, IT, ES and UK)
A6: 05 | B6: Mining of coal | C6: =AVERAGEIFS(decay_nem_eu!$D:$D,decay_nem_eu!$C:$C,{"FR";"DE";"IT";"ES";"UK"},decay_nem_eu!$A:$A,"02") -> 0.052445378 | D6: NEMESIS EU (avg value from DE, FR, IT, ES and UK)
A7: 06 | B7: Extraction of oil | C7: =AVERAGEIFS(decay_nem_eu!$D:$D,decay_nem_eu!$C:$C,{"FR";"DE";"IT";"ES";"UK"},decay_nem_eu!$A:$A,"03") -> 0.049447983 | D7: NEMESIS EU (avg value from DE, FR, IT, ES and UK)
A8: 07 | B8: Extraction of natural gas | C8: =AVERAGEIFS(decay_nem_eu!$D:$D,decay_nem_eu!$C:$C,{"FR";"DE";"IT";"ES";"UK"},decay_nem_eu!$A:$A,"03") -> 0.049447983 | D8: NEMESIS EU (avg value from DE, FR, IT, ES and UK)
A9: 08 | B9: Other mining | C9: =AVERAGEIFS(decay_nem_eu!$D:$D,decay_nem_eu!$C:$C,{"FR";"DE";"IT";"ES";"UK"},decay_nem_eu!$A:$A,{"02";"03"}) -> 0.052445378 | D9: NEMESIS EU (avg value from DE, FR, IT, ES and UK)
A10: 09 | B10: Manufacture of food, beverage and tobacco | C10: =AVERAGEIFS(decay_nem_eu!$D:$D,decay_nem_eu!$C:$C,{"FR";"DE";"IT";"ES";"UK"},decay_nem_eu!$A:$A,"16") -> 0.058778332 | D10: NEMESIS EU (avg value from DE, FR, IT, ES and UK)
A11: 10 | B11: Manufacture of textiles, wearing apparel and leather products | C11: =AVERAGEIFS(decay_nem_eu!$D:$D,decay_nem_eu!$C:$C,{"FR";"DE";"IT";"ES";"UK"},decay_nem_eu!$A:$A,"17") -> 0.060746243 | D11: NEMESIS EU (avg value from DE, FR, IT, ES and UK)
A12: 11 | B12: Manufacture of wood and wood products | C12: =AVERAGEIFS(decay_nem_eu!$D:$D,decay_nem_eu!$C:$C,{"FR";"DE";"IT";"ES";"UK"},decay_nem_eu!$A:$A,"18") -> 0.059333507 | D12: NEMESIS EU (avg value from DE, FR, IT, ES and UK)
A13: 12 | B13: Manufacture of pulp, paper and printing products | C13: =AVERAGEIFS(decay_nem_eu!$D:$D,decay_nem_eu!$C:$C,{"FR";"DE";"IT";"ES";"UK"},decay_nem_eu!$A:$A,"18") -> 0.059333507 | D13: NEMESIS EU (avg value from DE, FR, IT, ES and UK)
A14: 13 | B14: Manufacture of coke | C14: =AVERAGEIFS(decay_nem_eu!$D:$D,decay_nem_eu!$C:$C,{"FR";"DE";"IT";"ES";"UK"},decay_nem_eu!$A:$A,"05") -> 0.058137151 | D14: NEMESIS EU (avg value from DE, FR, IT, ES and UK)
A15: 14 | B15: Manufacture of petroleum and nuclear products | C15: =AVERAGEIFS(decay_nem_eu!$D:$D,decay_nem_eu!$C:$C,{"FR";"DE";"IT";"ES";"UK"},decay_nem_eu!$A:$A,"05") -> 0.058137151 | D15: NEMESIS EU (avg value from DE, FR, IT, ES and UK)
A16: 15 | B16: Chemicals - platics | C16: =AVERAGEIFS(decay_nem_eu!$D:$D,decay_nem_eu!$C:$C,{"FR";"DE";"IT";"ES";"UK"},decay_nem_eu!$A:$A,"10") -> 0.061660232 | D16: NEMESIS EU (avg value from DE, FR, IT, ES and UK)
A17: 16 | B17: Chemicals - fertilisers | C17: =AVERAGEIFS(decay_nem_eu!$D:$D,decay_nem_eu!$C:$C,{"FR";"DE";"IT";"ES";"UK"},decay_nem_eu!$A:$A,"10") -> 0.061660232 | D17: NEMESIS EU (avg value from DE, FR, IT, ES and UK)
A18: 17 | B18: Cheminals - others | C18: =AVERAGEIFS(decay_nem_eu!$D:$D,decay_nem_eu!$C:$C,{"FR";"DE";"IT";"ES";"UK"},decay_nem_eu!$A:$A,"10") -> 0.061660232 | D18: NEMESIS EU (avg value from DE, FR, IT, ES and UK)
A19: 18 | B19: Manufacture of rubber and plactic products | C19: =AVERAGEIFS(decay_nem_eu!$D:$D,decay_nem_eu!$C:$C,{"FR";"DE";"IT";"ES";"UK"},decay_nem_eu!$A:$A,"19") -> 0.055632951 | D19: NEMESIS EU (avg value from DE, FR, IT, ES and UK)
A20: 19 | B20: Manufacture of glass | C20: =AVERAGEIFS(decay_nem_eu!$D:$D,decay_nem_eu!$C:$C,{"FR";"DE";"IT";"ES";"UK"},decay_nem_eu!$A:$A,"09") -> 0.050111405 | D20: NEMESIS EU (avg value from DE, FR, IT, ES and UK)
A21: 20 | B21: Manufacture of cement and lime | C21: =AVERAGEIFS(decay_nem_eu!$D:$D,decay_nem_eu!$C:$C,{"FR";"DE";"IT";"ES";"UK"},decay_nem_eu!$A:$A,"09") -> 0.050111405 | D21: NEMESIS EU (avg value from DE, FR, IT, ES and UK)
A22: 21 | B22: Manufacture of other non-metallic mineral products | C22: =AVERAGEIFS(decay_nem_eu!$D:$D,decay_nem_eu!$C:$C,{"FR";"DE";"IT";"ES";"UK"},decay_nem_eu!$A:$A,"09") -> 0.050111405 | D22: NEMESIS EU (avg value from DE, FR, IT, ES and UK)
A23: 22 | B23: Manufacture of iron and steel | C23: =AVERAGEIFS(decay_nem_eu!$D:$D,decay_nem_eu!$C:$C,{"FR";"DE";"IT";"ES";"UK"},decay_nem_eu!$A:$A,"08") -> 0.055183114 | D23: NEMESIS EU (avg value from DE, FR, IT, ES and UK)
A24: 23 | B24: Manufacture of other basic metals | C24: =AVERAGEIFS(decay_nem_eu!$D:$D,decay_nem_eu!$C:$C,{"FR";"DE";"IT";"ES";"UK"},decay_nem_eu!$A:$A,"08") -> 0.055183114 | D24: NEMESIS EU (avg value from DE, FR, IT, ES and UK)
A25: 24 | B25: Aluminium production | C25: =AVERAGEIFS(decay_nem_eu!$D:$D,decay_nem_eu!$C:$C,{"FR";"DE";"IT";"ES";"UK"},decay_nem_eu!$A:$A,"08") -> 0.055183114 | D25: NEMESIS EU (avg value from DE, FR, IT, ES and UK)
A26: 25 | B26: Manufacture of fabricated metal products | C26: =AVERAGEIFS(decay_nem_eu!$D:$D,decay_nem_eu!$C:$C,{"FR";"DE";"IT";"ES";"UK"},decay_nem_eu!$A:$A,"11") -> 0.056656435 | D26: NEMESIS EU (avg value from DE, FR, IT, ES and UK)
A27: 26 | B27: Manufacture of machinery and equipment | C27: =AVERAGEIFS(decay_nem_eu!$D:$D,decay_nem_eu!$C:$C,{"FR";"DE";"IT";"ES";"UK"},decay_nem_eu!$A:$A,"12") -> 0.054135413 | D27: NEMESIS EU (avg value from DE, FR, IT, ES and UK)
A28: 27 | B28: Manufacture of office machinery and computers | C28: =AVERAGEIFS(decay_nem_eu!$D:$D,decay_nem_eu!$C:$C,{"FR";"DE";"IT";"ES";"UK"},decay_nem_eu!$A:$A,"13") -> 0.060097132 | D28: NEMESIS EU (avg value from DE, FR, IT, ES and UK)
A29: 28 | B29: Manufacture of electrical machinery and apparatus | C29: =AVERAGEIFS(decay_nem_eu!$D:$D,decay_nem_eu!$C:$C,{"FR";"DE";"IT";"ES";"UK"},decay_nem_eu!$A:$A,"14") -> 0.054620515 | D29: NEMESIS EU (avg value from DE, FR, IT, ES and UK)
A30: 29 | B30: Manufacture of radio, television and communication equipment and apparatus | C30: =AVERAGEIFS(decay_nem_eu!$D:$D,decay_nem_eu!$C:$C,{"FR";"DE";"IT";"ES";"UK"},decay_nem_eu!$A:$A,"14") -> 0.054620515 | D30: NEMESIS EU (avg value from DE, FR, IT, ES and UK)
A31: 30 | B31: Manufacture of medical, precision and optical instruments, watches and clocks | C31: =AVERAGEIFS(decay_nem_eu!$D:$D,decay_nem_eu!$C:$C,{"FR";"DE";"IT";"ES";"UK"},decay_nem_eu!$A:$A,"14") -> 0.054620515 | D31: NEMESIS EU (avg value from DE, FR, IT, ES and UK)
A32: 31 | B32: Manufacture of motor vehicles, trailers and semi-trailers | C32: =AVERAGEIFS(decay_nem_eu!$D:$D,decay_nem_eu!$C:$C,{"FR";"DE";"IT";"ES";"UK"},decay_nem_eu!$A:$A,"15") -> 0.058136386 | D32: NEMESIS EU (avg value from DE, FR, IT, ES and UK)
A33: 32 | B33: Manufacture of other transport equipment | C33: =AVERAGEIFS(decay_nem_eu!$D:$D,decay_nem_eu!$C:$C,{"FR";"DE";"IT";"ES";"UK"},decay_nem_eu!$A:$A,"15") -> 0.058136386 | D33: NEMESIS EU (avg value from DE, FR, IT, ES and UK)
A34: 33 | B34: Other manufacturing | C34: =AVERAGEIFS(decay_nem_eu!$D:$D,decay_nem_eu!$C:$C,{"FR";"DE";"IT";"ES";"UK"},decay_nem_eu!$A:$A,"20") -> 0.071428571 | D34: NEMESIS EU (avg value from DE, FR, IT, ES and UK)
A35: 34 | B35: Wastes treatment and recycling | C35: =AVERAGEIFS(decay_nem_eu!$D:$D,decay_nem_eu!$C:$C,{"FR";"DE";"IT";"ES";"UK"},decay_nem_eu!$A:$A,"20") -> 0.071428571 | D35: NEMESIS EU (avg value from DE, FR, IT, ES and UK)
A36: 35 | B36: Production of electricity | C36: =AVERAGEIFS(decay_nem_eu!$D:$D,decay_nem_eu!$C:$C,{"FR";"DE";"IT";"ES";"UK"},decay_nem_eu!$A:$A,"06") -> 0.051976885 | D36: NEMESIS EU (avg value from DE, FR, IT, ES and UK)
A37: 36 | B37: Transmission of electricity | C37: =AVERAGEIFS(decay_nem_eu!$D:$D,decay_nem_eu!$C:$C,{"FR";"DE";"IT";"ES";"UK"},decay_nem_eu!$A:$A,"06") -> 0.051976885 | D37: NEMESIS EU (avg value from DE, FR, IT, ES and UK)
A38: 37 | B38: Distribution and trade of electricity | C38: =AVERAGEIFS(decay_nem_eu!$D:$D,decay_nem_eu!$C:$C,{"FR";"DE";"IT";"ES";"UK"},decay_nem_eu!$A:$A,"06") -> 0.051976885 | D38: NEMESIS EU (avg value from DE, FR, IT, ES and UK)
A39: 38 | B39: Manufacture of gas; distribution of gaseous fuels through mains | C39: =AVERAGEIFS(decay_nem_eu!$D:$D,decay_nem_eu!$C:$C,{"FR";"DE";"IT";"ES";"UK"},decay_nem_eu!$A:$A,"06") -> 0.051976885 | D39: NEMESIS EU (avg value from DE, FR, IT, ES and UK)
A40: 39 | B40: Steam and hot water supply | C40: =AVERAGEIFS(decay_nem_eu!$D:$D,decay_nem_eu!$C:$C,{"FR";"DE";"IT";"ES";"UK"},decay_nem_eu!$A:$A,"06") -> 0.051976885 | D40: NEMESIS EU (avg value from DE, FR, IT, ES and UK)
...

Sheet sigma
A1: parameter | B1: sec_cd | C1: sec_nm | D1: value | E1: source
A2: sigma_prod | B2: 01 | C2: Agriculture - vegetable
A3: sigma_prod | B3: 02 | C3: Agriculture - animals
A4: sigma_prod | B4: 03 | C4: Forestry
A5: sigma_prod | B5: 04 | C5: Fishery
A6: sigma_prod | B6: 05 | C6: Mining of coal
A7: sigma_prod | B7: 06 | C7: Extraction of oil
A8: sigma_prod | B8: 07 | C8: Extraction of natural gas
A9: sigma_prod | B9: 08 | C9: Other mining
A10: sigma_prod | B10: 09 | C10: Manufacture of food, beverage and tobacco
A11: sigma_prod | B11: 10 | C11: Manufacture of textiles, wearing apparel and leather products
A12: sigma_prod | B12: 11 | C12: Manufacture of wood and wood products
A13: sigma_prod | B13: 12 | C13: Manufacture of pulp, paper and printing products
... A60: sigma_prod | B60: 59 | C60: Other services activities

Sheet decay_nem_eu
A1: 01 | B1: 1 Agriculture | C1: AT | D1: 0.07246975
A2: 02 | B2: 2 Coal and Coke | C2: AT | D2: 0.050896695
A3: 03 | B3: 3 Oil & Gas Extraction | C3: AT | D3: 0.053423079
A4: 04 | B4: 4 Gas Distribution | C4: AT | D4: 0.045469926
A5: 05 | B5: 5 Refined Oil | C5: AT | D5: 0.053297681
A6: 06 | B6: 6 Electricity | C6: AT | D6: 0.052811246
A7: 07 | B7: 7 Water Supply | C7: AT | D7: 0.045541844
A8: 08 | B8: 8 Ferr & non Ferrous Metals | C8: AT | D8: 0.056842692
A9: 09 | B9: 9 Non Metallic Min Products | C9: AT | D9: 0.049308221
A10: 10 | B10: 10 Chemicals | C10: AT | D10: 0.061340851
A11: 11 | B11: 11 Metal Products | C11: AT | D11: 0.056711526
A12: 12 | B12: 12 Agr & Indus Machines | C12: AT | D12: 0.056879472
... A337: 07 | B337: 7 Water Supply | C337: PT | D337: 0.045622842
A338: 08 | B338: 8 Ferr & non Ferrous Metals | C338: PT | D338: #DIV/0!
A339: 09 | B339: 9 Non Metallic Min Products | C339: PT | D339: 0.049635126
A340: 10 | B340: 10 Chemicals | C340: PT | D340: 0.062061119
A341: 11 | B341: 11 Metal Products | C341: PT | D341: 0.055923629
A342: 12 | B342: 12 Agr & Indus Machines | C342: PT | D342: 0.056010039
A343: 13 | B343: 13 Office machines | C343: PT | D343: #DIV/0!
A344: 14 | B344: 14 Electrical Goods | C344: PT | D344: 0.054568852
A345: 15 | B345: 15 transport Equipment | C345: PT | D345: 0.06081923
A346: 16 | B346: 16 Food, Drink & Tobacco | C346: PT | D346: 0.058423683
A347: 17 | B347: 17 Tex., Cloth & Footw. | C347: PT | D347: 0.061487843
A348: 18 | B348: 18 Paper & Printing Products | C348: PT | D348: 0.061277294
A349: 19 | B349: 19 Rubber & Plastic | C349: PT | D349: 0.055758076
A350: 20 | B350: 20 Other Manufactures | C350: PT | D350: 0.071428571
A351: 21 | B351: 21 Construction | C351: PT | D351: 0.077277585
A352: 22 | B352: 22 Distribution | C352: PT | D352: 0.075461754
A353: 23 | B353: 23 Lodging & Catering | C353: PT | D353: 0.044182644
A354: 24 | B354: 24 Inland Transports | C354: PT | D354: 0.088427226
A355: 25 | B355: 25 Sea & Air Transport | C355: PT | D355: 0.042045944
... A930: 30 | B930: 30 Non Market Services | C930: CH | D930: 0.051140911

Sheet icebergcost
B1: OE | C1: DE | D1: ES | E1: FR | F1: IT | G1: UK | H1: US | I1: JP | J1: CN | K1: CA | L1: KR | M1: BR | N1: IN | O1: MX | P1: RU | Q1: AU | R1: WE | S1: WA | T1: ID | U1: WF | V1: WL | W1: WM
A2: OE | B2: 1 | C2: 1.0266 | D2: 1.1178 | E2: 1.0703 | F2: 1.0677 | G2: 1.0745 | H2: 1.3694 | I2: 1.4414 | J2: 1.3572 | K2: 1.3385 | L2: 1.3983 | M2: 1.516 | N2: 1.2709 | O2: 1.5239 | P2: 1.0592 | Q2: 1.8007 | R2: 1.0547 | S2: 1.4163 | T2: 1.5285 | U2: 1.2877 | V2: 1.6344 | W2: 1.1928
A3: DE | B3: 1.0266 | C3: 1 | D3: 1.0962 | E3: 1.0452 | F3: 1.0609 | G3: 1.0479 | H3: 1.3453 | I3: 1.4588 | J3: 1.3786 | K3: 1.3154 | L3: 1.4182 | M3: 1.4936 | N3: 1.2975 | O3: 1.5006 | P3: 1.0828 | Q3: 1.8268 | R3: 1.0431 | S3: 1.4427 | T3: 1.5552 | U3: 1.2758 | V3: 1.6129 | W3: 1.2143
A4: ES | B4: 1.1178 | C4: 1.0962 | D4: 1 | E4: 1.0542 | F4: 1.0702 | G4: 1.065 | H4: 1.3133 | I4: 1.5538 | J4: 1.4746 | K4: 1.2928 | L4: 1.5144 | M4: 1.3981 | N4: 1.3743 | O4: 1.4664 | P4: 1.177 | Q4: 1.9043 | R4: 1.1229 | S4: 1.524 | T4: 1.6273 | U4: 1.1924 | V4: 1.5169 | W4: 1.2552
A5: FR | B5: 1.0703 | C5: 1.0452 | D5: 1.0542 | E5: 1 | F5: 1.0569 | G5: 1.0177 | H5: 1.3173 | I5: 1.4998 | J5: 1.4229 | K5: 1.2907 | L5: 1.4614 | M5: 1.449 | N5: 1.339 | O5: 1.4733 | P5: 1.1279 | Q5: 1.8707 | R5: 1.0691 | S5: 1.486 | T5: 1.5962 | U5: 1.2433 | V5: 1.5687 | W5: 1.2407
A6: IT | B6: 1.0677 | C6: 1.0609 | D6: 1.0702 | E6: 1.0569 | F6: 1 | G6: 1.0738 | H6: 1.3714 | I6: 1.507 | J6: 1.4181 | K6: 1.3463 | L6: 1.4614 | M6: 1.4583 | N6: 1.3045 | O6: 1.527 | P6: 1.1222 | Q6: 1.8345 | R6: 1.1032 | S6: 1.4543 | T6: 1.5572 | U6: 1.2201 | V6: 1.5739 | W6: 1.1889
A7: UK | B7: 1.0745 | C7: 1.0479 | D7: 1.065 | E7: 1.0177 | F7: 1.0738 | G7: 1 | H7: 1.3035 | I7: 1.4919 | J7: 1.419 | K7: 1.2759 | L7: 1.4558 | M7: 1.4525 | N7: 1.3454 | O7: 1.4595 | P7: 1.1287 | Q7: 1.8739 | R7: 1.0594 | S7: 1.4905 | T7: 1.603 | U7: 1.2568 | V7: 1.5727 | W7: 1.2542
A8: US | B8: 1.3694 | C8: 1.3453 | D8: 1.3133 | E8: 1.3173 | F8: 1.3714 | G8: 1.3035 | H8: 1 | I8: 1.5613 | J8: 1.5736 | K8: 1.0377 | L8: 1.5745 | M8: 1.3497 | N8: 1.6199 | O8: 1.156 | P8: 1.4025 | Q8: 1.8205 | R8: 1.3207 | S8: 1.7284 | T8: 1.8418 | U8: 1.4094 | V8: 1.4321 | W8: 1.5577
A9: JP | B9: 1.4414 | C9: 1.4588 | D9: 1.5538 | E9: 1.4998 | F9: 1.507 | G9: 1.4919 | H9: 1.5613 | I9: 1 | J9: 1.1075 | K9: 1.5313 | L9: 1.0592 | M9: 1.9099 | N9: 1.3002 | O9: 1.582 | P9: 1.3848 | Q9: 1.4092 | R9: 1.4325 | S9: 1.2367 | T9: 1.2975 | U9: 1.7223 | V9: 1.9455 | W9: 1.4471
A10: CN | B10: 1.3572 | C10: 1.3786 | D10: 1.4746 | E10: 1.4229 | F10: 1.4181 | G10: 1.419 | H10: 1.5736 | I10: 1.1075 | J10: 1 | K10: 1.5378 | L10: 1.049 | M10: 1.8714 | N10: 1.1945 | O10: 1.6411 | P10: 1.2982 | Q10: 1.4636 | R10: 1.3615 | S10: 1.1696 | T10: 1.2687 | U10: 1.6232 | V10: 1.9915 | W10: 1.3397
A11: CA | B11: 1.3385 | C11: 1.3154 | D11: 1.2928 | E11: 1.2907 | F11: 1.3463 | G11: 1.2759 | H11: 1.0377 | I11: 1.5313 | J11: 1.5378 | K11: 1 | L11: 1.541 | M11: 1.3788 | N11: 1.5835 | O11: 1.1854 | P11: 1.3684 | Q11: 1.829 | R11: 1.2881 | S11: 1.6908 | T11: 1.8053 | U11: 1.4088 | V11: 1.4666 | W11: 1.5293
A12: KR | B12: 1.3983 | C12: 1.4182 | D12: 1.5144 | E12: 1.4614 | F12: 1.4614 | G12: 1.4558 | H12: 1.5745 | I12: 1.0592 | J12: 1.049 | K12: 1.541 | L12: 1 | M12: 1.9028 | N12: 1.2412 | O12: 1.6202 | P12: 1.3399 | Q12: 1.4331 | R12: 1.3971 | S12: 1.1915 | T12: 1.2726 | U12: 1.6706 | V12: 2 | W12: 1.3886
A13: BR | B13: 1.516 | C13: 1.4936 | D13: 1.3981 | E13: 1.449 | F13: 1.4583 | G13: 1.4525 | H13: 1.3497 | I13: 1.9099 | J13: 1.8714 | K13: 1.3788 | L13: 1.9028 | M13: 1 | N13: 1.7326 | O13: 1.3518 | P13: 1.5752 | Q13: 1.7235 | R13: 1.5099 | S13: 1.8549 | T13: 1.8394 | U13: 1.2738 | V13: 1.1204 | W13: 1.5754
... A23: WM | B23: 1.1928 | C23: 1.2143 | D23: 1.2552 | E23: 1.2407 | F23: 1.1889 | G23: 1.2542 | H23: 1.5577 | I23: 1.4471 | J23: 1.3397 | K23: 1.5293 | L23: 1.3886 | M23: 1.5754 | N23: 1.1573 | O23: 1.7137 | P23: 1.1816 | Q23: 1.6504 | R23: 1.2465 | S23: 1.2957 | T23: 1.3787 | U23: 1.3018 | V23: 1.6614 | W23: 1

Sheet vat_rate
A1: region | B1: sector | C1: vat_rate
A2: AU | B2: 01 | C2: 0
A3: AU | B3: 02 | C3: 0
A4: AU | B4: 03 | C4: 0
A5: AU | B5: 04 | C5: 0
A6: AU | B6: 05 | C6: 0.1
A7: AU | B7: 06 | C7: 0.1
A8: AU | B8: 07 | C8: 0.1
A9: AU | B9: 08 | C9: 0.1
A10: AU | B10: 09 | C10: 0
A11: AU | B11: 10 | C11: 0.1
A12: AU | B12: 11 | C12: 0.1
A13: AU | B13: 12 | C13: 0.1
... A1299: WM | B1299: 59 | C1299: 0.15

Sheet source
A1: vat rate: | B1: https://www.oecd.org/content/dam/oecd/en/publications/reports/2024/11/consumption-tax-trends-2024_57c7322a/dcd4dd36-en.pdf
B2: https://www.ato.gov.au/businesses-and-organisations/gst-excise-and-indirect-taxes/gst/when-to-charge-gst-and-when-not-to/gst-free-sales
B3: https://www.fzcoltd.com/brazil-sales-tax-everything-you-need-to-know/
B4: https://www.vatcalc.com/china/china-vat-exemption-tackles-real-estate-collapse/
B5: https://www.canada.ca/en/revenue-agency/services/tax/businesses/topics/gst-hst-businesses/charge-collect-which-rate.html
B6: https://taxsummaries.pwc.com/japan/corporate/other-taxes
