Workbook

Sheet inflr
A1: vars | B1: 2015Y1 | C1: 2016Y1 | D1: 2017Y1 | E1: 2018Y1 | F1: 2019Y1 | G1: 2020Y1 | H1: 2021Y1 | I1: 2022Y1 | J1: 2023Y1 | K1: 2024Y1
A2: INFL_AU | B2: =Table!E8/100 -> 0.01508367 | C2: =Table!F8/100 -> 0.01276991 | D2: =Table!G8/100 -> 0.01948647 | E2: =Table!H8/100 -> 0.01911401 | F2: =Table!I8/100 -> 0.01610768 | G2: =Table!J8/100 -> 0.008469055 | H2: =Table!K8/100 -> 0.0286391 | I2: =Table!L8/100 -> 0.06594097 | ... K2: =Table!N8/100 -> 0.03161614
A3: INFL_BR | B3: =Table!E52/100 -> 0.09029901 | C3: =Table!F52/100 -> 0.08739143 | D3: =Table!G52/100 -> 0.03446373 | E3: =Table!H52/100 -> 0.0366485 | F3: =Table!I52/100 -> 0.03732976 | G3: =Table!J52/100 -> 0.03211768 | H3: =Table!K52/100 -> 0.0830166 | I3: =Table!L52/100 -> 0.09280107 | ... K3: =Table!N52/100 -> 0.04367464
A4: INFL_CA | B4: =Table!E11/100 -> 0.01125241 | C4: =Table!F11/100 -> 0.0142876 | D4: =Table!G11/100 -> 0.01596884 | E4: =Table!H11/100 -> 0.02268226 | F4: =Table!I11/100 -> 0.01949269 | G4: =Table!J11/100 -> 0.007169997 | H4: =Table!K11/100 -> 0.03395193 | I4: =Table!L11/100 -> 0.06802801 | ... K4: =Table!N11/100 -> 0.02381584
A5: INFL_CN | B5: =Table!E54/100 -> 0.01437024 | C5: =Table!F54/100 -> 0.02 | D5: =Table!G54/100 -> 0.01593137 | E5: =Table!H54/100 -> 0.02074789 | F5: =Table!I54/100 -> 0.02899236 | G5: =Table!J54/100 -> 0.02419417 | H5: =Table!K54/100 -> 0.009810191 | I5: =Table!L54/100 -> 0.01973576 | ... K5: =Table!N54/100 -> 0.002181289
A6: INFL_DE | B6: =Table!E20/100 -> 0.00514421 | C6: =Table!F20/100 -> 0.004917486 | D6: =Table!G20/100 -> 0.01509497 | E6: =Table!H20/100 -> 0.01732168 | F6: =Table!I20/100 -> 0.01445667 | G6: =Table!J20/100 -> 0.001448705 | H6: =Table!K20/100 -> 0.03066667 | I6: =Table!L20/100 -> 0.06872574 | ... K6: =Table!N20/100 -> 0.02256498
A7: INFL_ES | B7: =Table!E39/100 -> -0.005003657 | C7: =Table!F39/100 -> -0.00202598 | D7: =Table!G39/100 -> 0.01956076 | E7: =Table!H39/100 -> 0.01674981 | F7: =Table!I39/100 -> 0.00699519 | G7: =Table!J39/100 -> -0.00322753 | H7: =Table!K39/100 -> 0.03093135 | I7: =Table!L39/100 -> 0.08390576 | ... K7: =Table!N39/100 -> 0.02774178
A8: INFL_FR | B8: =Table!E19/100 -> 0.0003751438 | C8: =Table!F19/100 -> 0.001833349 | D8: =Table!G19/100 -> 0.01032283 | E8: =Table!H19/100 -> 0.01850815 | F8: =Table!I19/100 -> 0.01108255 | G8: =Table!J19/100 -> 0.004764988 | H8: =Table!K19/100 -> 0.01642331 | I8: =Table!L19/100 -> 0.05222367 | ... K8: =Table!N19/100 -> 0.01999049
A9: INFL_ID | B9: =Table!E56/100 -> 0.05872427 | C9: =Table!F56/100 -> 0.04941027 | D9: =Table!G56/100 -> 0.02490887 | E9: =Table!H56/100 -> 0.048607 | F9: =Table!I56/100 -> 0.07659695 | G9: =Table!J56/100 -> 0.05561349 | H9: =Table!K56/100 -> 0.04890086 | I9: =Table!L56/100 -> 0.0590043 | ... K9: =Table!N56/100 -> 0.03800098
A10: INFL_IN | B10: =Table!E57/100 -> 0.06363121 | C10: =Table!F57/100 -> 0.03525805 | D10: =Table!G57/100 -> 0.03808798 | E10: =Table!H57/100 -> 0.03198346 | F10: =Table!I57/100 -> 0.03030587 | G10: =Table!J57/100 -> 0.01919834 | H10: =Table!K57/100 -> 0.0156008 | I10: =Table!L57/100 -> 0.04209456 | ... K10: =Table!N57/100 -> 0.02181507
A11: INFL_IT | B11: =Table!E26/100 -> 0.0003878675 | C11: =Table!F26/100 -> -0.000940214 | D11: =Table!G26/100 -> 0.01226533 | E11: =Table!H26/100 -> 0.01137488 | F11: =Table!I26/100 -> 0.006112469 | G11: =Table!J26/100 -> -0.001377076 | H11: =Table!K26/100 -> 0.01873783 | I11: =Table!L26/100 -> 0.0820129 | ... K11: =Table!N26/100 -> 0.00982373
A12: INFL_JP | B12: =Table!E27/100 -> 0.008 | C12: =Table!F27/100 -> -0.001 | D12: =Table!G27/100 -> 0.004841998 | E12: =Table!H27/100 -> 0.009890946 | F12: =Table!I27/100 -> 0.004687762 | G12: =Table!J27/100 -> -0.0002499583 | H12: =H6 -> 0.03066667 | I12: =I6 -> 0.06872574 | J12: =J6 -> 0.05946437 | K12: =K6 -> 0.02256498
A13: INFL_KR | B13: =Table!E28/100 -> 0.007063318 | C13: =Table!F28/100 -> 0.009716858 | D13: =Table!G28/100 -> 0.01944332 | E13: =Table!H28/100 -> 0.01475839 | F13: =Table!I28/100 -> 0.003830003 | G13: =Table!J28/100 -> 0.00537288 | H13: =Table!K28/100 -> 0.02498333 | I13: =Table!L28/100 -> 0.05089514 | ... K13: =Table!N28/100 -> 0.02321743
A14: INFL_MX | B14: =Table!E32/100 -> 0.02720641 | C14: =Table!F32/100 -> 0.02821708 | D14: =Table!G32/100 -> 0.06041456 | E14: =Table!H32/100 -> 0.04899351 | F14: =Table!I32/100 -> 0.03635961 | G14: =Table!J32/100 -> 0.03396834 | H14: =Table!K32/100 -> 0.05689209 | I14: =Table!L32/100 -> 0.07896276 | J14: =Table!M32/100 -> 0.05527961 | K14: =J14 -> 0.05527961
A15: INFL_OE | B15: =Table!E48/100 -> 0.001 | C15: =Table!F48/100 -> 0.002 | D15: =Table!G48/100 -> 0.016 | E15: =Table!H48/100 -> 0.018 | F15: =Table!I48/100 -> 0.014 | G15: =Table!J48/100 -> 0.007 | H15: =Table!K48/100 -> 0.029 | I15: =Table!L48/100 -> 0.092 | ... K15: =Table!N48/100 -> 0.026
A16: INFL_RU | B16: =Table!E58/100 -> 0.155344 | C16: =Table!F58/100 -> 0.07042436 | D16: =Table!G58/100 -> 0.03683334 | E16: =Table!H58/100 -> 0.02878305 | F16: =Table!I58/100 -> 0.04470367 | G16: =Table!J58/100 -> 0.0338166 | H16: =Table!K58/100 -> 0.06694456 | I16: =H16 -> 0.06694456 | J16: =I16 -> 0.06694456 | K16: =J16 -> 0.06694456
A17: INFL_UK | B17: =Table!E43/100 -> 0.004016064 | C17: =Table!F43/100 -> 0.01 | D17: =Table!G43/100 -> 0.02574257 | E17: =Table!H43/100 -> 0.02316602 | F17: =Table!I43/100 -> 0.01698113 | G17: =Table!J43/100 -> 0.01020408 | H17: =Table!K43/100 -> 0.02479339 | I17: =Table!L43/100 -> 0.0797491 | ... K17: =Table!N43/100 -> 0.03343701
A18: INFL_US | B18: =Table!E44/100 -> 0.001186271 | C18: =Table!F44/100 -> 0.01261583 | D18: =Table!G44/100 -> 0.0213011 | E18: =Table!H44/100 -> 0.02442583 | F18: =Table!I44/100 -> 0.0181221 | G18: =Table!J44/100 -> 0.01233584 | H18: =Table!K44/100 -> 0.04697859 | I18: =Table!L44/100 -> 0.080028 | ... K18: =Table!N44/100 -> 0.02949525
A19: INFL_WA | B19: =Table!E57/100 -> 0.06363121 | C19: =Table!F57/100 -> 0.03525805 | D19: =Table!G57/100 -> 0.03808798 | E19: =Table!H57/100 -> 0.03198346 | F19: =Table!I57/100 -> 0.03030587 | G19: =Table!J57/100 -> 0.01919834 | H19: =Table!K57/100 -> 0.0156008 | I19: =Table!L57/100 -> 0.04209456 | ... K19: =Table!N57/100 -> 0.02181507
A20: INFL_WE | B20: =Table!E34/100 -> 0.02171137 | C20: =Table!F34/100 -> 0.0355 | D20: =Table!G34/100 -> 0.01875101 | E20: =Table!H34/100 -> 0.02764831 | F20: =Table!I34/100 -> 0.0216773 | G20: =Table!J34/100 -> 0.01286585 | H20: =Table!K34/100 -> 0.03483881 | I20: =Table!L34/100 -> 0.05764123 | ... K20: =Table!N34/100 -> 0.03145301
A21: INFL_WF | B21: =Table!E60/100 -> 0.04518691 | C21: =Table!F60/100 -> 0.06602909 | D21: =Table!G60/100 -> 0.05186187 | E21: =Table!H60/100 -> 0.04509872 | F21: =Table!I60/100 -> 0.04102851 | G21: =Table!J60/100 -> 0.03232388 | H21: =Table!K60/100 -> 0.04618745 | I21: =Table!L60/100 -> 0.07039873 | ... K21: =Table!N60/100 -> 0.04361153
A22: INFL_WL | B22: =Table!E52/100 -> 0.09029901 | C22: =Table!F52/100 -> 0.08739143 | D22: =Table!G52/100 -> 0.03446373 | E22: =Table!H52/100 -> 0.0366485 | F22: =Table!I52/100 -> 0.03732976 | G22: =Table!J52/100 -> 0.03211768 | H22: =Table!K52/100 -> 0.0830166 | I22: =Table!L52/100 -> 0.09280107 | ... K22: =Table!N52/100 -> 0.04367464
A23: INFL_WM | B23: =Table!E59/100 -> 0.01204692 | C23: =Table!F59/100 -> 0.0206741 | D23: =Table!G59/100 -> -0.008364107 | E23: =Table!H59/100 -> 0.0245719 | F23: =Table!I59/100 -> -0.02093341 | G23: =Table!J59/100 -> 0.03445467 | H23: =Table!K59/100 -> 0.0306329 | I23: =Table!L59/100 -> 0.02474074 | ... K23: =Table!N59/100 -> 0.01687921

Sheet Table
B1: (DSD_PRICES@DF_PRICES_ALL) Consumer price indices (CPIs, HICPs), COICOP 1999
B2: (FREQ) Frequency of observation: (A) Annual
B3: (COMBINED_MEASURE) Measure: (CPI, N, G1) Consumer price index, National, Growth rate, period on period
B4: (COMBINED_UNIT_MEASURE) Unit of measure: (PC, N) Percentage change
B6: (TIME_PERIOD) Time period | C6: (TIME_PERIOD) Time period | D6: (2014) 2014 | E6: (2015) 2015 | F6: (2016) 2016 | G6: (2017) 2017 | H6: (2018) 2018 | I6: (2019) 2019 | J6: (2020) 2020 | K6: (2021) 2021 | L6: (2022) 2022 | M6: (2023) 2023 | N6: (2024) 2024
B7: (REF_AREA) Reference area
B8: (AUS) Australia | D8: 2.487923 | E8: 1.508367 | F8: 1.276991 | G8: 1.948647 | H8: 1.911401 | I8: 1.610768 | J8: 0.8469055 | K8: 2.86391 | L8: 6.594097 | M8: 5.597015 | N8: 3.161614
B9: (AUT) Austria | D9: 1.605806 | E9: 0.8965653 | F9: 0.8915924 | G9: 2.081269 | H9: 1.998382 | I9: 1.530896 | J9: 1.381909 | K9: 2.766667 | L9: 8.54687 | M9: 7.814134 | N9: 2.937916
B10: (BEL) Belgium | D10: 0.3400028 | E10: 0.5614291 | F10: 1.973853 | G10: 2.125971 | H10: 2.053165 | I10: 1.43682 | J10: 0.7407918 | K10: 2.440248 | L10: 9.597511 | M10: 4.049011 | N10: 3.143491
B11: (CAN) Canada | D11: 1.906636 | E11: 1.125241 | F11: 1.42876 | G11: 1.596884 | H11: 2.268226 | I11: 1.949269 | J11: 0.7169997 | K11: 3.395193 | L11: 6.802801 | M11: 3.879002 | N11: 2.381584
B12: (CHL) Chile | D12: 4.718675 | E12: 4.348773 | F12: 3.786194 | G12: 2.182719 | H12: 2.43489 | I12: 2.557545 | J12: 3.045491 | K12: 4.524569 | L12: 11.64387 | M12: 7.581683
B13: (COL) Colombia | D13: 2.898838 | E13: 4.989829 | F13: 7.513461 | G13: 4.314313 | H13: 3.24057 | I13: 3.52302 | J13: 2.52662 | K13: 3.495073 | L13: 10.17724 | M13: 11.7359 | N13: 6.609091
B14: (CRI) Costa Rica | D14: 4.519201 | E14: 0.801982 | F14: -0.01747885 | G14: 1.625907 | H14: 2.221115 | I14: 2.096046 | J14: 0.7249115 | K14: 1.726478
B15: (CZE) Czechia | D15: 0.3439886 | E15: 0.3093646 | F15: 0.6835042 | G15: 2.450534 | H15: 2.149495 | I15: 2.847876 | J15: 3.161295 | K15: 3.839845 | L15: 15.10017 | M15: 10.66126 | N15: 2.435312
B16: (DNK) Denmark | D16: 0.5640205 | E16: 0.4520341 | F16: 0.25 | G16: 1.147132 | H16: 0.8136095 | I16: 0.7581316 | J16: 0.420712 | K16: 1.853045 | L16: 7.696567 | M16: 3.305178 | N16: 1.3722
B17: (EST) Estonia | D17: -0.1061751 | E17: -0.492326 | F17: 0.1486849 | G17: 3.417236 | H17: 3.436327 | I17: 2.277259 | J17: -0.4445311 | K17: 4.653167 | L17: 19.39826 | M17: 9.159226 | N17: 3.520561
B18: (FIN) Finland | D18: 1.0412 | E18: -0.207932 | F18: 0.3566845 | G18: 0.754015 | H18: 1.083821 | I18: 1.024094 | J18: 0.2905546 | K18: 2.194574 | L18: 7.123507 | M18: 6.250643 | N18: 1.565689
B19: (FRA) France | D19: 0.5077588 | E19: 0.03751438 | F19: 0.1833349 | G19: 1.032283 | H19: 1.850815 | I19: 1.108255 | J19: 0.4764988 | K19: 1.642331 | L19: 5.222367 | M19: 4.878357 | N19: 1.999049
B20: (DEU) Germany | D20: 0.9067971 | E20: 0.514421 | F20: 0.4917486 | G20: 1.509497 | H20: 1.732168 | I20: 1.445667 | J20: 0.1448705 | K20: 3.066667 | L20: 6.872574 | M20: 5.946437 | N20: 2.256498
B21: (GRC) Greece | D21: -1.312242 | E21: -1.735902 | F21: -0.8256576 | G21: 1.121259 | H21: 0.6256205 | I21: 0.2529927 | J21: -1.247972 | K21: 1.223826 | L21: 9.645261 | M21: 3.464802 | N21: 2.741496
B22: (HUN) Hungary | D22: -0.2275663 | E22: -0.06164468 | F22: 0.3947693 | G22: 2.348243 | H22: 2.850248 | I22: 3.338586 | J22: 3.326744 | K22: 5.110965 | L22: 14.60814 | M22: 17.12497 | N22: 3.703704
B23: (ISL) Iceland | D23: 2.044619 | E23: 1.633058 | F23: 1.69693 | G23: 1.760413 | H23: 2.682915 | I23: 3.013977 | J23: 2.847919 | K23: 4.444243 | L23: 8.308754 | M23: 8.736306 | N23: 5.856838
B24: (IRL) Ireland | D24: 0.1909164 | E24: -0.3309598 | F24: 0.02012477 | G24: 0.3621731 | H24: 0.4711307 | I24: 0.937843 | J24: -0.3261836 | K24: 2.340341 | L24: 7.829457 | M24: 6.299425 | N24: 2.11345
B25: (ISR) Israel | D25: 0.4675573 | E25: -0.6173426 | F25: -0.5351682 | G25: 0.2498078 | H25: 0.8050604 | I25: 0.817646 | J25: -0.5752546 | K25: 1.479655 | L25: 4.411627 | M25: 4.225226 | N25: 3.074809
B26: (ITA) Italy | D26: 0.2410575 | E26: 0.03878675 | F26: -0.0940214 | G26: 1.226533 | H26: 1.137488 | I26: 0.6112469 | J26: -0.1377076 | K26: 1.873783 | L26: 8.20129 | M26: 5.622194 | N26: 0.982373
B27: (JPN) Japan | D27: 2.7 | E27: 0.8 | F27: -0.1 | G27: 0.4841998 | H27: 0.9890946 | I27: 0.4687762 | J27: -0.02499583
B28: (KOR) Korea | D28: 1.274774 | E28: 0.7063318 | F28: 0.9716858 | G28: 1.944332 | H28: 1.475839 | I28: 0.3830003 | J28: 0.537288 | K28: 2.498333 | L28: 5.089514 | M28: 3.597456 | N28: 2.321743
B29: (LVA) Latvia | D29: 0.6204923 | E29: 0.1742414 | F29: 0.1406308 | G29: 2.930369 | H29: 2.53446 | I29: 2.811403 | J29: 0.2190611 | K29: 3.275814 | L29: 17.31029 | M29: 8.938056 | N29: 1.265798
B30: (LTU) Lithuania | D30: 0.103758 | E30: -0.8840974 | F30: 0.9055251 | G30: 3.722889 | H30: 2.697928 | I30: 2.334509 | J30: 1.199894 | K30: 4.683544 | L30: 19.70505 | M30: 9.11732 | N30: 0.7157359
B31: (LUX) Luxembourg | D31: 0.628544 | E31: 0.4747432 | F31: 0.2908333 | G31: 1.7308 | H31: 1.528195 | I31: 1.743321 | J31: 0.8199573 | K31: 2.52692 | L31: 6.336008 | M31: 3.741404 | N31: 2.051133
B32: (MEX) Mexico | D32: 4.018617 | E32: 2.720641 | F32: 2.821708 | G32: 6.041456 | H32: 4.899351 | I32: 3.635961 | J32: 3.396834 | K32: 5.689209 | L32: 7.896276 | M32: 5.527961
B33: (NLD) Netherlands | D33: 0.9760351 | E33: 0.6002482 | F33: 0.3166667 | G33: 1.381459 | H33: 1.703498 | I33: 2.633699 | J33: 1.27246 | K33: 2.67572 | L33: 10.00121 | M33: 3.838393 | N33: 3.347543
B34: (NOR) Norway | D34: 2.041703 | E34: 2.171137 | F34: 3.55 | G34: 1.875101 | H34: 2.764831 | I34: 2.16773 | J34: 1.286585 | K34: 3.483881 | L34: 5.764123 | M34: 5.51785 | N34: 3.145301
B35: (POL) Poland | D35: -0.075 | E35: -0.05833333 | F35: 0.075 | G35: 0.1666667 | H35: 0.1 | I35: 0.2666667 | J35: 0.1916667 | K35: 0.7 | L35: 1.3 | M35: 0.5 | N35: 0.3833333
B36: (PRT) Portugal | D36: -0.2781534 | E36: 0.4879386 | F36: 0.6073971 | G36: 1.368614 | H36: 0.9937157 | I36: 0.3381784 | J36: -0.01243833 | K36: 1.265657 | L36: 7.832691 | M36: 4.311282 | N36: 2.416132
B37: (SVK) Slovak Republic | D37: -0.07616533 | E37: -0.3252198 | F37: -0.5200102 | G37: 1.311946 | H37: 2.514037 | I37: 2.664561 | J37: 1.936941 | K37: 3.149606 | L37: 12.77415 | M37: 10.53195 | N37: 2.757609
B38: (SVN) Slovenia | D38: 0.1993438 | E38: -0.5255523 | F38: -0.05499954 | G38: 1.429107 | H38: 1.738609 | I38: 1.630523 | J38: -0.05485681 | K38: 1.917065 | L38: 8.833699 | M38: 7.446877 | N38: 1.965627
B39: (ESP) Spain | D39: -0.1511148 | E39: -0.5003657 | F39: -0.202598 | G39: 1.956076 | H39: 1.674981 | I39: 0.699519 | J39: -0.322753 | K39: 3.093135 | L39: 8.390576 | M39: 3.532361 | N39: 2.774178
B40: (SWE) Sweden | D40: -0.1796385 | E40: -0.04678474 | F40: 0.9842693 | G40: 1.794499 | H40: 1.953535 | I40: 1.784151 | J40: 0.4973673 | K40: 2.163197 | L40: 8.369291 | M40: 8.548625 | N40: 2.835817
B41: (CHE) Switzerland | D41: -0.01320254 | E41: -1.143909 | F41: -0.4346187 | G41: 0.5337878 | H41: 0.9363354 | I41: 0.3628862 | J41: -0.725875 | K41: 0.5818142 | L41: 2.835028 | M41: 2.135401 | N41: 1.06234
...

Sheet Overview
B1: (DSD_PRICES@DF_PRICES_ALL) Consumer price indices (CPIs, HICPs), COICOP 1999
B2: <p style='margin-top:0cm;margin-right:0cm;margin-bottom:0cm;margin-left:0cm;font-size:15px;font-family:"Calibri",sans-serif;background:white;'><span style="color:black;">This dataset contains statistics on Consumer Price Indices by COICOP 1999 divisions, including national CPIs, Harmonised Indices of Consumer Prices (HICPs) and their associated weights and contributions to national year-on-year inflation. For countries for which data are already available according to the COICOP 2018 classification statistics on Consumer Price Indices can be found in dataset&nbsp;</span><u><span style='font-family:"Roboto Slab";color:#494444;'>Consumer price indices (CPIs, HICPs), COICOP 2018</span></u><span style='font-family:"Roboto Slab";color:#494444;'>.&nbsp;</span><span style="color:black;">The data series presented have been chosen as the most relevant prices statistics for which comparable data across countries is available. Data are available monthly for all the countries except for Australia and New Zealand (quarterly data).
B5: Topic: Economy > Prices
B7: Number of unfiltered data points: 2742177
B8: Last updated: October 17, 2025 at 4:21:41 AM
B11: You might also be interested in these data:
B12: Contribution to year-on-year inflation by COICOP 1999 by country
B13: Eurostat harmonised index of consumer prices (HICP)
B14: Eurostat harmonised index of consumer prices (HICP), Item weights, All countries, All items
B15: National CPI, Growth rate over one year, All countries, All items less food and energy, COICOP 1999
B16: National CPI, Growth rate over one year, All countries, Energy, COICOP 1999
B17: National CPI, Growth rate over one year, All countries, Food and non-alcoholic beverages, COICOP 1999
B18: National CPI, Item weights, COICOP 1999, All countries, All items
