Workbook

Sheet rzrl
A1: vars | B1: 2015Y1 | C1: 2016Y1 | D1: 2017Y1 | E1: 2018Y1 | F1: 2019Y1 | G1: 2020Y1 | H1: 2021Y1 | I1: 2022Y1 | J1: 2023Y1 | K1: 2024Y1
A2: RZLR_AU | B2: =+Table!B8/100 -> 0.053660417 | C2: =+Table!C8/100 -> 0.048795833 | D2: =+Table!D8/100 -> 0.033791667 | E2: =+Table!E8/100 -> 0.037230417 | F2: =+Table!F8/100 -> 0.036638333 | G2: =+Table!G8/100 -> 0.027205 | H2: =+Table!H8/100 -> 0.023408333 | I2: =+Table!I8/100 -> 0.0264125 | ... K2: =+Table!K8/100 -> 0.014970833
A3: RZLR_BR | B3: =Table!B46/100 -> 0.06 | C3: =Table!C46/100 -> 0.06 | D3: =Table!D46/100 -> 0.0575 | E3: =Table!E46/100 -> 0.05 | F3: =Table!F46/100 -> 0.05 | G3: =Table!G46/100 -> 0.0625 | H3: =Table!H46/100 -> 0.075 | I3: =Table!I46/100 -> 0.07125 | ... K3: =Table!K46/100 -> 0.062025
A4: RZLR_CA | B4: =Table!B11/100 -> 0.0323514 | C4: =Table!C11/100 -> 0.027830361 | D4: =Table!D11/100 -> 0.018734101 | E4: =Table!E11/100 -> 0.022619588 | F4: =Table!F11/100 -> 0.022308303 | G4: =Table!G11/100 -> 0.015216946 | H4: =Table!H11/100 -> 0.012517576 | I4: =Table!I11/100 -> 0.01783652 | ... K4: =Table!K11/100 -> 0.015887419
A5: RZLR_CN | B5: =C5 -> 0.041041167 | C5: =D5 -> 0.041041167 | D5: =E5 -> 0.041041167 | E5: =F5 -> 0.041041167 | F5: =Table!F47/100 -> 0.041041167 | G5: =Table!G47/100 -> 0.033338833 | H5: =Table!H47/100 -> 0.028500667 | I5: =Table!I47/100 -> 0.035916667 | J5: =Table!J47/100 -> 0.035791667 | K5: =Table!K47/100 -> 0.031813
A6: RZLR_DE | B6: =Table!B20/100 -> 0.027442674 | C6: =Table!C20/100 -> 0.02609185 | D6: =Table!D20/100 -> 0.014951302 | E6: =Table!E20/100 -> 0.01571408 | F6: =Table!F20/100 -> 0.011634723 | G6: =Table!G20/100 -> 0.0049519368 | H6: =Table!H20/100 -> 0.00091499192 | I6: =Table!I20/100 -> 0.0031633611 | ... K6: =Table!K20/100 -> -0.0025363446
A7: RZLR_ES | B7: =Table!B39/100 -> 0.042500009 | C7: =Table!C39/100 -> 0.054368942 | D7: =Table!D39/100 -> 0.058465372 | E7: =Table!E39/100 -> 0.04561962 | F7: =Table!F39/100 -> 0.027218311 | G7: =Table!G39/100 -> 0.017350873 | H7: =Table!H39/100 -> 0.013933022 | I7: =Table!I39/100 -> 0.015578658 | ... K7: =Table!K39/100 -> 0.0066101833
A8: RZLR_FR | B8: =Table!B19/100 -> 0.031183333 | C8: =Table!C19/100 -> 0.0332 | D8: =Table!D19/100 -> 0.025366667 | E8: =Table!E19/100 -> 0.022041667 | F8: =Table!F19/100 -> 0.016666667 | G8: =Table!G19/100 -> 0.008425 | H8: =Table!H19/100 -> 0.0046666667 | I8: =Table!I19/100 -> 0.0080916667 | ... K8: =Table!K19/100 -> 0.0013083333
A9: RZLR_ID | B9: =C9 -> 0.0826 | C9: =D9 -> 0.0826 | D9: =Table!D49/100 -> 0.0826 | E9: =Table!E49/100 -> 0.081091667 | F9: =Table!F49/100 -> 0.085866667 | G9: =Table!G49/100 -> 0.077766667 | H9: =Table!H49/100 -> 0.07205 | I9: =Table!I49/100 -> 0.069225 | J9: =Table!J49/100 -> 0.077041667 | K9: =Table!K49/100 -> 0.069966667
A10: RZLR_IN | B10: =C10 -> 0.057958333 | C10: =D10 -> 0.057958333 | D10: =Table!D50/100 -> 0.057958333 | E10: =Table!E50/100 -> 0.069875 | F10: =Table!F50/100 -> 0.081316667 | G10: =Table!G50/100 -> 0.082216667 | H10: =Table!H50/100 -> 0.076383333 | I10: =Table!I50/100 -> 0.068783333 | J10: =Table!J50/100 -> 0.074575 | K10: =Table!K50/100 -> 0.074653
A11: RZLR_IT | B11: =Table!B26/100 -> 0.040358333 | C11: =Table!C26/100 -> 0.054228333 | D11: =Table!D26/100 -> 0.0549275 | E11: =Table!E26/100 -> 0.043164167 | F11: =Table!F26/100 -> 0.028931667 | G11: =Table!G26/100 -> 0.017139167 | H11: =Table!H26/100 -> 0.014863333 | I11: =Table!I26/100 -> 0.02113 | ... K11: =Table!K26/100 -> 0.019515
A12: RZLR_JP | B12: =Table!B27/100 -> 0.011483333 | C12: =Table!C27/100 -> 0.011024167 | D12: =Table!D27/100 -> 0.0083558333 | E12: =Table!E27/100 -> 0.0068966667 | F12: =Table!F27/100 -> 0.0052033333 | G12: =Table!G27/100 -> 0.0035 | H12: =Table!H27/100 -> -0.0006625 | I12: =Table!I27/100 -> 0.00051666667 | ... K12: =Table!K27/100 -> -0.0011041667
A13: RZLR_KR | B13: =Table!B28/100 -> 0.047733333 | C13: =Table!C28/100 -> 0.042025 | D13: =Table!D28/100 -> 0.034475 | E13: =Table!E28/100 -> 0.032780833 | F13: =Table!F28/100 -> 0.031863333 | G13: =Table!G28/100 -> 0.0230575 | H13: =Table!H28/100 -> 0.017474167 | I13: =Table!I28/100 -> 0.022825833 | ... K13: =Table!K28/100 -> 0.0170225
A14: RZLR_MX | B14: =B3 -> 0.06 | C14: =C3 -> 0.06 | D14: =D3 -> 0.0575 | E14: =E3 -> 0.05 | F14: =F3 -> 0.05 | G14: =G3 -> 0.0625 | H14: =H3 -> 0.075 | I14: =I3 -> 0.07125 | ... K14: =K3 -> 0.062025
A15: RZLR_OE | B15: =Table!B44/100 -> 0.037814045 | C15: =Table!C44/100 -> 0.043079524 | D15: =Table!D44/100 -> 0.030476509 | E15: =Table!E44/100 -> 0.030117759 | F15: =Table!F44/100 -> 0.022813497 | G15: =Table!G44/100 -> 0.012674751 | H15: =Table!H44/100 -> 0.0092856539 | I15: =Table!I44/100 -> 0.011707339 | ... K15: =Table!K44/100 -> 0.0058461464
A16: RZLR_RU | B16: =Table!B51/100 -> 0.078316667 | C16: =Table!C51/100 -> 0.080608333 | D16: =Table!D51/100 -> 0.081541667 | E16: =Table!E51/100 -> 0.073308333 | F16: =Table!F51/100 -> 0.084641667 | G16: =Table!G51/100 -> 0.10886667 | H16: =Table!H51/100 -> 0.10438333 | I16: =Table!I51/100 -> 0.089925 | J16: =I16 -> 0.089925 | K16: =J16 -> 0.089925
A17: RZLR_UK | B17: =Table!B42/100 -> 0.03624425 | C17: =Table!C42/100 -> 0.031359917 | D17: =Table!D42/100 -> 0.019180417 | E17: =Table!E42/100 -> 0.023897833 | F17: =Table!F42/100 -> 0.025690833 | G17: =Table!G42/100 -> 0.019010333 | H17: =Table!H42/100 -> 0.013052083 | I17: =Table!I42/100 -> 0.012358083 | ... K17: =Table!K42/100 -> 0.00935825
A18: RZLR_US | B18: =Table!B43/100 -> 0.032141667 | C18: =Table!C43/100 -> 0.027858333 | D18: =Table!D43/100 -> 0.018025 | E18: =Table!E43/100 -> 0.023508333 | F18: =Table!F43/100 -> 0.025408333 | G18: =Table!G43/100 -> 0.021358333 | H18: =Table!H43/100 -> 0.018416667 | I18: =Table!I43/100 -> 0.0233 | ... K18: =Table!K43/100 -> 0.021441667
A19: RZLR_WA | B19: =Table!B8/100 -> 0.053660417 | C19: =Table!C8/100 -> 0.048795833 | D19: =Table!D8/100 -> 0.033791667 | E19: =Table!E8/100 -> 0.037230417 | F19: =Table!F8/100 -> 0.036638333 | G19: =Table!G8/100 -> 0.027205 | H19: =Table!H8/100 -> 0.023408333 | I19: =Table!I8/100 -> 0.0264125 | ... K19: =Table!K8/100 -> 0.014970833
A20: RZLR_WE | B20: =Table!B34/100 -> 0.035283333 | C20: =Table!C34/100 -> 0.03135 | D20: =Table!D34/100 -> 0.021016667 | E20: =Table!E34/100 -> 0.025775 | F20: =Table!F34/100 -> 0.02515 | G20: =Table!G34/100 -> 0.01565 | H20: =Table!H34/100 -> 0.013316667 | I20: =Table!I34/100 -> 0.016375 | ... K20: =Table!K34/100 -> 0.014941667
A21: RZLR_WF | B21: =Table!B52/100 -> 0.086154163 | C21: =Table!C52/100 -> 0.08514085 | D21: =Table!D52/100 -> 0.079027988 | E21: =Table!E52/100 -> 0.077195941 | F21: =Table!F52/100 -> 0.082438534 | G21: =Table!G52/100 -> 0.081591514 | H21: =Table!H52/100 -> 0.090168406 | I21: =Table!I52/100 -> 0.090540017 | ... K21: =Table!K52/100 -> 0.090725748
A22: RZLR_WL | B22: =Table!B46/100 -> 0.06 | C22: =Table!C46/100 -> 0.06 | D22: =Table!D46/100 -> 0.0575 | E22: =Table!E46/100 -> 0.05 | F22: =Table!F46/100 -> 0.05 | G22: =Table!G46/100 -> 0.0625 | H22: =Table!H46/100 -> 0.075 | I22: =Table!I46/100 -> 0.07125 | ... K22: =Table!K46/100 -> 0.062025
A23: RZLR_WM | B23: =Table!B25/100 -> 0.046841667 | C23: =Table!C25/100 -> 0.0498 | D23: =Table!D25/100 -> 0.043991667 | E23: =Table!E25/100 -> 0.037958333 | F23: =Table!F25/100 -> 0.028858333 | G23: =Table!G25/100 -> 0.0207 | H23: =Table!H25/100 -> 0.018791667 | I23: =Table!I25/100 -> 0.019091667 | ... K23: =Table!K25/100 -> 0.014683333

Sheet Overview
B1: Key short-term economic indicators
B2: The Key Economic Indicators (KEI) database contains monthly and quarterly statistics (and associated statistical methodological information) for all OECD member countries and for a selection of non-member countries on a wide variety of economic indicators, namely: quarterly national accounts, industrial production, composite leading indicators, business tendency and consumer opinion surveys, retail trade, consumer and producer prices, hourly earnings, employment/unemployment, interest rates, monetary aggregates, exchange rates, international trade and balance of payments.<p />Indicators have been prepared by national statistical agencies primarily to meet the requirements of users within their own country. In most instances, the indicators are compiled in accordance with international statistical guidelines and recommendations. However, national practices may depart from these guidelines, and these departures may impact on comparability between countries. There is an on-going process of review and revision of the contents of the database in order to maximise the relevance of the database for short-term economic analysis.<p /><a href=mailto:stat.contact@oecd.org>OECD statistics contact</a><p /><a href="http://www.oecd.org/sdd">Statistics and Data Directorate</a>
B5: Topic: Economy > Short-term economic statistics
B7: Number of unfiltered data points: 1571595
B8: Last updated: July 14, 2025 at 3:14:12 AM

Sheet Table
A1: Key short-term economic indicators
A2: Frequency of observation: Annual
A3: Measure: Long-term interest rates
A4: Unit of measure: Percent per annum
A6: Time period | B6: 2010 | C6: 2011 | D6: 2012 | E6: 2013 | F6: 2014 | G6: 2015 | H6: 2016 | I6: 2017 | J6: 2018 | K6: 2019 | L6: 2020 | M6: 2021 | N6: 2022 | O6: 2023 | P6: 2024
A7: Reference area
A8: Australia | B8: 5.3660417 | C8: 4.8795833 | D8: 3.3791667 | E8: 3.7230417 | F8: 3.6638333 | G8: 2.7205 | H8: 2.3408333 | I8: 2.64125 | J8: 2.6816667 | K8: 1.4970833 | L8: 0.92016667 | M8: 1.47975 | N8: 3.1965 | O8: 3.9420833 | P8: 4.20975
A9: Austria | B9: 3.2263833 | C9: 3.3196583 | D9: 2.371175 | E9: 2.0107583 | F9: 1.4872917 | G9: 0.74704167 | H9: 0.37538333 | I9: 0.58328333 | J9: 0.68615833 | K9: 0.062933333 | L9: -0.22485 | M9: -0.085383333 | N9: 1.71115 | O9: 3.082675 | P9: 2.8427083
A10: Belgium | B10: 3.4625 | C10: 4.2333333 | D10: 3 | E10: 2.41 | F10: 1.7133333 | G10: 0.84 | H10: 0.47583333 | I10: 0.7225 | J10: 0.795 | K10: 0.19333333 | L10: -0.14833333 | M10: -0.014166667 | N10: 1.7333333 | O10: 3.0891667 | P10: 2.925
A11: Canada | B11: 3.23514 | C11: 2.7830361 | D11: 1.8734101 | E11: 2.2619588 | F11: 2.2308303 | G11: 1.5216946 | H11: 1.2517576 | I11: 1.783652 | J11: 2.2779121 | K11: 1.5887419 | L11: 0.75310866 | M11: 1.3588111 | N11: 2.7685796 | O11: 3.3606393 | P11: 3.3398444
A12: Chile | B12: 6.2528741 | C12: 5.9696446 | D12: 5.4255705 | E12: 5.3087371 | F12: 4.7366153 | G12: 4.4802215 | H12: 4.4052768 | I12: 4.2449583 | J12: 4.4978573 | K12: 3.5778866 | L12: 2.7985631 | M12: 4.3615901 | N12: 6.2600223 | O12: 5.6557995 | P12: 5.7889376
A13: Colombia | B13: 8.4658333 | C13: 8.0883333 | D13: 6.8133333 | E13: 6.495 | F13: 7.0558333 | G13: 7.8541667 | H13: 7.9058333 | I13: 6.7716667 | J13: 6.9958333 | K13: 6.4975 | L13: 6.3333333 | M13: 7.6241667 | N13: 11.684167 | O13: 11.339167 | P13: 10.773333
A14: Costa Rica | F14: 9.8366667 | G14: 9.63 | H14: 8.335 | I14: 8.9066667 | J14: 9.9625 | K14: 10.616667 | L14: 8.8366667 | M14: 7.9333333 | N14: 8.0183333 | O14: 8.1066667 | P14: 6.5216667
A15: Czechia | B15: 3.885424 | C15: 3.7071225 | D15: 2.7818408 | E15: 2.1118045 | F15: 1.5754712 | G15: 0.57394769 | H15: 0.42710852 | I15: 0.98036249 | J15: 1.9811234 | K15: 1.548116 | L15: 1.1287859 | M15: 1.9034683 | N15: 4.3335337 | O15: 4.4384321 | P15: 3.9799142
A16: Denmark | B16: 2.9260833 | C16: 2.72925 | D16: 1.4034167 | E16: 1.745 | F16: 1.3248333 | G16: 0.6905 | H16: 0.32033333 | I16: 0.47641667 | J16: 0.45483333 | K16: -0.18341667 | L16: -0.35925 | M16: -0.060833333 | N16: 1.47775 | O16: 2.67775 | P16: 2.3030833
A17: Estonia | M17: 0.063333333 | N17: 2.2858333 | O17: 3.9008333 | P17: 3.5466667
A18: Finland | B18: 3.0108333 | C18: 3.0058333 | D18: 1.8833333 | E18: 1.8608333 | F18: 1.4483333 | G18: 0.72333333 | H18: 0.365 | I18: 0.54666667 | J18: 0.66166667 | K18: 0.07 | L18: -0.21916667 | M18: -0.095076037 | N18: 1.6553077 | O18: 3.0375 | P18: 2.8529677
A19: France | B19: 3.1183333 | C19: 3.32 | D19: 2.5366667 | E19: 2.2041667 | F19: 1.6666667 | G19: 0.8425 | H19: 0.46666667 | I19: 0.80916667 | J19: 0.78333333 | K19: 0.13083333 | L19: -0.145 | M19: 0.0066666667 | N19: 1.7008333 | O19: 2.9941667 | P19: 2.9691667
A20: Germany | B20: 2.7442674 | C20: 2.609185 | D20: 1.4951302 | E20: 1.571408 | F20: 1.1634723 | G20: 0.49519368 | H20: 0.091499192 | I20: 0.31633611 | J20: 0.39636398 | K20: -0.25363446 | L20: -0.51102401 | M20: -0.37382117 | N20: 1.142583 | O20: 2.4345987 | P20: 2.3210841
A21: Greece | B21: 9.0916667 | C21: 15.749167 | D21: 22.4975 | E21: 10.054167 | F21: 6.9291667 | G21: 9.6663636 | H21: 8.36 | I21: 5.9783333 | J21: 4.185 | K21: 2.5858333 | L21: 1.2716667 | M21: 0.88416667 | N21: 3.4866667 | O21: 4.0016667 | P21: 3.35
A22: Hungary | B22: 7.2816667 | C22: 7.6354087 | D22: 7.8908333 | E22: 5.9233333 | F22: 4.8091667 | G22: 3.4325 | H22: 3.1433333 | I22: 2.9625 | J22: 3.0583333 | K22: 2.465 | L22: 2.225 | M22: 3.0608333 | N22: 7.5708333 | O22: 7.5125 | P22: 6.5008333
A23: Iceland | B23: 3.4933333 | C23: 2.9466667 | D23: 2.2766667 | E23: 2.5516667 | F23: 3.2016667 | G23: 2.6608333 | H23: 2.7758333 | I23: 2.2158333 | J23: 1.8425 | K23: 1.0858333 | L23: 0.34083333 | M23: 0.77833333
A24: Ireland | B24: 5.7391667 | C24: 9.6016667 | D24: 6.1716667 | E24: 3.79 | F24: 2.3675 | G24: 1.1825 | H24: 0.73583333 | I24: 0.80166667 | J24: 0.95184167 | K24: 0.33105833 | L24: -0.061041667 | M24: 0.063158333 | N24: 1.7456167 | O24: 2.8666167 | P24: 2.7175833
A25: Israel | B25: 4.6841667 | C25: 4.98 | D25: 4.3991667 | E25: 3.7958333 | F25: 2.8858333 | G25: 2.07 | H25: 1.8791667 | I25: 1.9091667 | J25: 1.9941667 | K25: 1.4683333 | L25: 0.7775 | M25: 1.1166667 | N25: 2.6191667 | O25: 3.8680833 | P25: 4.6766667
A26: Italy | B26: 4.0358333 | C26: 5.4228333 | D26: 5.49275 | E26: 4.3164167 | F26: 2.8931667 | G26: 1.7139167 | H26: 1.4863333 | I26: 2.113 | J26: 2.6103333 | K26: 1.9515 | L26: 1.1681667 | M26: 0.81091667 | N26: 3.15675 | O26: 4.28325 | P26: 3.7074167
A27: Japan | B27: 1.1483333 | C27: 1.1024167 | D27: 0.83558333 | E27: 0.68966667 | F27: 0.52033333 | G27: 0.35 | H27: -0.06625 | I27: 0.051666667 | J27: 0.065 | K27: -0.11041667 | L27: -0.0054166667 | M27: 0.071666667 | N27: 0.23166667 | O27: 0.5625 | P27: 0.91833333
A28: Korea | B28: 4.7733333 | C28: 4.2025 | D28: 3.4475 | E28: 3.2780833 | F28: 3.1863333 | G28: 2.30575 | H28: 1.7474167 | I28: 2.2825833 | J28: 2.50275 | K28: 1.70225 | L28: 1.4996667 | M28: 2.0645 | N28: 3.3635 | O28: 3.6423333 | P28: 3.21925
A29: Latvia | B29: 10.3375 | C29: 5.9075 | D29: 4.565 | E29: 3.34 | F29: 2.5083333 | G29: 0.96333333 | H29: 0.53416667 | I29: 0.83416667 | J29: 0.9025 | K29: 0.3425 | L29: -0.0625 | M29: -0.0025 | N29: 2.2725 | O29: 3.8283333 | P29: 3.2875
A30: Lithuania | B30: 5.5666667 | C30: 5.16 | D30: 4.8308333 | E30: 3.8316667 | F30: 2.7925 | G30: 1.3808333 | H30: 0.89833333 | I30: 0.31 | J30: 0.31 | K30: 0.31 | L30: 0.22333333 | M30: 0.16 | N30: 0.61333333 | O30: 2.88 | P30: 2.88
A31: Luxembourg | B31: 3.1691667 | C31: 2.9233333 | D31: 1.821 | E31: 1.8509167 | F31: 1.3368333 | G31: 0.36875 | H31: 0.25425 | I31: 0.54483333 | J31: 0.56466667 | K31: -0.12058333 | L31: -0.41358333 | M31: -0.35658333 | N31: 1.7275 | O31: 2.9665 | P31: 2.7639167
A32: Netherlands | B32: 2.9900833 | C32: 2.9885833 | D32: 1.93225 | E32: 1.9605833 | F32: 1.4546667 | G32: 0.69033333 | H32: 0.29108333 | I32: 0.52208333 | J32: 0.57691667 | K32: -0.070166667 | L32: -0.37683333 | M32: -0.32808333 | N32: 1.3776667 | O32: 2.792 | P32: 2.6205
A33: New Zealand | B33: 5.6033333 | C33: 4.945 | D33: 3.685 | E33: 4.0933333 | F33: 4.3041667 | G33: 3.4233333 | H33: 2.7616667 | I33: 2.9908333 | J33: 2.7541667 | K33: 1.6491667 | L33: 0.89083333 | M33: 1.815 | N33: 3.6391667 | O33: 4.6241667 | P33: 4.5625
A34: Norway | B34: 3.5283333 | C34: 3.135 | D34: 2.1016667 | E34: 2.5775 | F34: 2.515 | G34: 1.565 | H34: 1.3316667 | I34: 1.6375 | J34: 1.8791667 | K34: 1.4941667 | L34: 0.8175 | M34: 1.4158704 | N34: 2.878413 | O34: 3.4355514 | P34: 3.5664418
A35: Poland | B35: 5.7816667 | C35: 5.9555833 | D35: 4.9992833 | E35: 4.0332917 | F35: 3.5162112 | G35: 2.7005565 | H35: 3.0356892 | I35: 3.42 | J35: 3.1983333 | K35: 2.3475 | L35: 1.4991667 | M35: 1.9441667 | N35: 6.0533333 | O35: 5.8058333 | P35: 5.525
... A44: Euro area (19 countries) | B44: 3.7814045 | C44: 4.3079524 | D44: 3.0476509 | E44: 3.0117759 | F44: 2.2813497 | G44: 1.2674751 | H44: 0.92856539 | I44: 1.1707339 | J44: 1.2640529 | K44: 0.58461464 | L44: 0.21358276 | M44: 0.19970029 | N44: 2.04145 | O44: 3.2651338 | P44: 2.9753046
A45: Non-OECD economies
A46: · Brazil | B46: 6 | C46: 6 | D46: 5.75 | E46: 5 | F46: 5 | G46: 6.25 | H46: 7.5 | I46: 7.125 | J46: 6.7225 | K46: 6.2025 | L46: 4.8725 | M46: 4.8 | N46: 6.7775 | O46: 7.05 | P46: 6.885
A47: · China (People’s Republic of) | F47: 4.1041167 | G47: 3.3338833 | H47: 2.8500667 | I47: 3.5916667 | J47: 3.5791667 | K47: 3.1813 | L47: 2.9244333 | M47: 3.0055333 | N47: 2.7641833 | O47: 2.715 | P47: 2.1816667
A48: · Croatia | B48: 6.265 | C48: 6.5391667 | D48: 6.1291667 | E48: 4.6808333 | F48: 4.0508333 | G48: 3.5266667 | H48: 3.475 | I48: 2.7675 | J48: 2.1725 | K48: 1.2875 | L48: 0.83333333 | M48: 0.4475 | N48: 2.6958333 | O48: 3.7958333 | P48: 3.31
A49: · India | D49: 8.26 | E49: 8.1091667 | F49: 8.5866667 | G49: 7.7766667 | H49: 7.205 | I49: 6.9225 | J49: 7.7041667 | K49: 6.9966667 | L49: 6.1916667 | M49: 6.2575 | N49: 7.1916667 | O49: 7.2183333 | P49: 6.9766667
...
